Workbook

Sheet Resumo
B2: MSI ENGENHARIA E TECNOLOGIA
B3: CONTRATO: 089/2026 — Ferro+ Mineração S.A — Sistema de Proteção contra Descargas Atmosféricas (SPDA)
B4: Resumo Geral — Painel de Acompanhamento
B6: =COUNTA(Controle!E4:E102) -> 98 | C6: =COUNTIF(Controle!Z4:Z102,"SPDA Conforme") -> 88 | D6: =COUNTIF(Controle!Z4:Z102,"Em andamento") -> 3 | E6: =COUNTIF(Controle!Z4:Z102,"SPDA Não Conforme") -> 1 | F6: =COUNTIF(Controle!Z4:Z102,"Paralisado/Novo Projeto") -> 1
B7: Áreas monitoradas | C7: Conformes (SPDA Conforme) | D7: Em andamento | E7: Não conformes | F7: Paralisadas / Novo Projeto
B8: =AVERAGE(Controle!P4:P102) -> 0.98355263 | C8: =COUNTIFS(Controle!AC4:AC102,"<>OK",Controle!AC4:AC102,"<>") -> 5 | D8: =COUNTIFS(Controle!T4:T102,"<"&TODAY(),Controle!T4:T102,"<>") -> 54 | E8: =COUNTIFS(Controle!T4:T102,">="&TODAY(),Controle!T4:T102,"<="&TODAY()+90) -> 0 | F8: =COUNTIFS(Controle!W4:W102,"<"&TODAY(),Controle!W4:W102,"<>") -> 90
B9: % Adequação média geral | C9: Pendências em aberto | D9: Laudos vencidos | E9: Laudos vencendo em 90 dias | F9: Inspeções (IS) vencidas
B10: =COUNTA(RIs!M4:M99) -> 0 | C10: =COUNTIF(RIs!O4:O99,"Aberta") -> 0 | D10: =COUNTIF(RIs!O4:O99,"Corrigida") -> 0
B11: Não conformidades registradas | C11: Não conformidades abertas | D11: Não conformidades corrigidas
B12: Distribuição de Status das Áreas Ativas
B13: Status | C13: Qtde
B14: SPDA Conforme | C14: =COUNTIF(Controle!Z4:Z102,"SPDA Conforme") -> 88
B15: Em andamento | C15: =COUNTIF(Controle!Z4:Z102,"Em andamento") -> 3
B16: SPDA Não Conforme | C16: =COUNTIF(Controle!Z4:Z102,"SPDA Não Conforme") -> 1
B17: Paralisado/Novo Projeto | C17: =COUNTIF(Controle!Z4:Z102,"Paralisado/Novo Projeto") -> 1
B18: Documentação Técnica Emitida
B19: Tipo de Documento | C19: Qtde Emitida
B20: Desenhos (DE) | C20: =COUNTA(Desenhos!A5:A93) -> 88
B21: Memoriais Descritivos (MD) | C21: =COUNTA(MDs!A4:A87) -> 84
B22: Listas de Materiais (LM) | C22: =COUNTA(LMs!A4:A89) -> 86
B23: Análises de Risco (MC) | C23: =COUNTA(MCs!A4:A98) -> 95
B24: Relatórios de Inspeção (RI) | C24: =COUNTA(RIs!A4:A99) -> 96

Sheet Desenhos
C1: Ferro+ - Ferro+ Mineração S.A
C2: CONTRATO: 089/2026 - Empresa: MSI Engenharia e Tecnologia LTDA
A3: OBJETO: Prestação de serviços de engenharia em formato de contrato ‘guarda-chuva’ para elaboração de estudos de análise de Riscos de Descarga Elétrica Atmosférica nas instalações da CONTRATANTE, localizados nos estados Minas Gerais, Espírito
A4: Número | B4: Obs.: | C4: Descrição da Área | D4: Título 1 | E4: Título 2 | F4: Título 3 | G4: Folhas | H4: Revisão | I4: Data de Emissão | J4: Número MSI | K4: Número J.Mendes
A5: K19-204-FER-DE-001 | C5: Planta Moinho de Rolos | D5: PROJETO EXECUTIVO DO SISTEMA DE PROTEÇÃO CONTRA DESCARGAS ATMOSFÉRICAS (SPDA) | E5: PLANTA MOINHO DE ROLOS | F5: PLANTA BAIXA, COBERTURA, CORTES A-A' E B-B' COM VOLUME PROTEGIDO | G5: 1 | H5: 0 | I5: 44075
A6: K19-204-FER-DE-002 | C6: Container Gestão de Contratos | D6: PROJETO EXECUTIVO DO SISTEMA DE PROTEÇÃO CONTRA DESCARGAS ATMOSFÉRICAS (SPDA) | E6: CONTAINER GESTÃO DE CONTRATOS | F6: PLANTA BAIXA, COBERTURA, CORTES A-A' E B-B' COM VOLUME PROTEGIDO | G6: 1 | H6: 0 | I6: 44075
A7: K19-204-FER-DE-003 | C7: Container RH Portaria | D7: PROJETO EXECUTIVO DO SISTEMA DE PROTEÇÃO CONTRA DESCARGAS ATMOSFÉRICAS (SPDA) | E7: CONTAINER RH PORTARIA | F7: PLANTA BAIXA, COBERTURA, CORTE A-A' E VOLUME PROTEGIDO | G7: 1 | H7: 0 | I7: 44075
A8: K19-204-FER-DE-004 | C8: Container RH Restaurante | D8: PROJETO EXECUTIVO DO SISTEMA DE PROTEÇÃO CONTRA DESCARGAS ATMOSFÉRICAS (SPDA) | E8: CONTAINER RH RESTAURANTE | F8: PLANTA BAIXA, COBERTURA, CORTE A-A' E VOLUME PROTEGIDO | G8: 1 | H8: 0 | I8: 44075
A9: K19-204-FER-DE-005 | C9: Container Fiscal Portaria | D9: PROJETO EXECUTIVO DO SISTEMA DE PROTEÇÃO CONTRA DESCARGAS ATMOSFÉRICAS (SPDA) | E9: CONTAINER FISCAL PORTARIA | F9: PLANTA BAIXA, COBERTURA, CORTE A-A' E VOLUME PROTEGIDO | G9: 1 | H9: 0 | I9: 44075
A10: K19-204-FER-DE-006 | C10: Container da Parada de Segurança | D10: PROJETO EXECUTIVO DO SISTEMA DE PROTEÇÃO CONTRA DESCARGAS ATMOSFÉRICAS (SPDA) | E10: CONTAINER DA PARADA DE SEGURANÇA | F10: PLANTA BAIXA, COBERTURA, CORTES A-A', B-B' E VOLUME PROTEGIDO | G10: 1 | H10: 0 | I10: 44075
A11: K19-204-FER-DE-007 | C11: Container Geotecnia | D11: PROJETO EXECUTIVO DO SISTEMA DE PROTEÇÃO CONTRA DESCARGAS ATMOSFÉRICAS (SPDA) | E11: CONTAINER GEOTECNIA | F11: PLANTA BAIXA, COBERTURA E CORTE A-A' COM VOLUME PROTEGIDO | G11: 1 | H11: 0 | I11: 44075
A12: K19-204-FER-DE-008 | C12: Containers próximo a Planta Piloto ITM | D12: PROJETO EXECUTIVO DO SISTEMA DE PROTEÇÃO CONTRA DESCARGAS ATMOSFÉRICAS (SPDA) | E12: CONTAINERS PRÓXIMO A PLANTA PILOTO ITM | F12: PLANTA BAIXA, COBERTURA, CORTES A-A', B-B', C-C' E D-D' COM VOLUME PROTEGIDO | G12: 1 | H12: 0 | I12: 44075
A13: K19-204-FER-DE-009 | C13: Escritório Geologia/Geotecnia | D13: PROJETO EXECUTIVO DO SISTEMA DE PROTEÇÃO CONTRA DESCARGAS ATMOSFÉRICAS (SPDA) | E13: ESCRITÓRIO GEOLOGIA/GEOTECNIA | F13: PLANTA BAIXA, COBERTURA, CORTES A-A' E B-B' COM VOLUME PROTEGIDO | G13: 1 | H13: 0 | I13: 44075
A14: K19-204-FER-DE-010 | C14: Oficina Caldeiraria | D14: PROJETO EXECUTIVO DO SISTEMA DE PROTEÇÃO CONTRA DESCARGAS ATMOSFÉRICAS (SPDA) | E14: OFICINA CALDEIRARIA | F14: PLANTA BAIXA, COBERTURA, CORTES A-A' E B-B' COM VOLUME PROTEGIDO | G14: 1 | H14: 0 | I14: 44075
A15: K19-204-FER-DE-011 | C15: Tanque Ácido Filtragem | D15: PROJETO EXECUTIVO DO SISTEMA DE PROTEÇÃO CONTRA DESCARGAS ATMOSFÉRICAS (SPDA) | E15: TANQUE ÁCIDO FILTRAGEM | F15: PLANTA BAIXA, COBERTURA, CORTES A-A' COM VOLUME PROTEGIDO | G15: 1 | H15: 0 | I15: 44075
A16: K19-204-FER-DE-012 | C16: Peneira Estática Mina | D16: PROJETO EXECUTIVO DO SISTEMA DE PROTEÇÃO CONTRA DESCARGAS ATMOSFÉRICAS (SPDA) | E16: PENEIRA ESTÁTICA MINA | F16: PLANTA BAIXA, COBERTURA, CORTES A-A' E B-B' COM VOLUME PROTEGIDO | G16: 1 | H16: 0 | I16: 44075
... A22: K19-204-FER-DE-018 | C22: Área de Classificação próxima ao Container do Meio Ambiente | D22: PROJETO EXECUTIVO DO SISTEMA DE PROTEÇÃO CONTRA DESCARGAS ATMOSFÉRICAS (SPDA) | E22: ÁREA DE CLASSIFICAÇÃO PRÓXIMO AO CONTAINER DO MEIO AMBIENTE | F22: PLANTA BAIXA, COBERTURA E CORTE A-A' COM VOLUME PROTEGIDO | G22: 1 | H22: 0 | I22: 44075
A23: K19-204-FER-DE-019 | B23: 20210369268 | C23: Oficina de Manutenção Peneiras Estáticas Cava Sul | D23: PROJETO EXECUTIVO DO SISTEMA DE PROTEÇÃO CONTRA DESCARGAS ATMOSFÉRICAS (SPDA) | E23: CONTAINER MANUTENÇÃO PENEIRA ESTÁTICA | F23: PLANTA BAIXA, COBERTURA, CORTES A-A' E B-B' COM VOLUME PROTEGIDO | G23: 1 | H23: 0 | I23: 44075
A24: K19-204-FER-DE-020 | C24: Ponto de Ônibus ITM | D24: PROJETO EXECUTIVO DO SISTEMA DE PROTEÇÃO CONTRA DESCARGAS ATMOSFÉRICAS (SPDA) | E24: PONTO DE ÔNIBUS ITM | F24: PLANTA BAIXA, COBERTURA, CORTE A-A' E VOLUME PROTEGIDO | G24: 1 | H24: 0 | I24: 44075
A25: K19-204-FER-DE-021 | B25: MG20210510755 | C25: Classificação, Rebritagens 1 e 2, Espirais e SE 138kV/CCM | D25: PROJETO EXECUTIVO DO SISTEMA DE PROTEÇÃO CONTRA DESCARGAS ATMOSFÉRICAS (SPDA) | E25: CLASSIFICAÇÃO, REBRITAGENS 1 E 2, ESPIRAIS E SE 138KV/CCM | F25: PLANTA BAIXA, COBERTURA, CORTES A-A', B-B', C-C' E D-D' COM VOLUME PROTEGIDO | G25: 1 | H25: 0 | I25: 44136
A26: K19-204-FER-DE-022 | C26: Separador Magnético, Floculantes e Espessadores | D26: PROJETO EXECUTIVO DO SISTEMA DE PROTEÇÃO CONTRA DESCARGAS ATMOSFÉRICAS (SPDA) | E26: SEPARADOR MAGNÉTICO, FLOCULANTES E ESPESSADORES | F26: PLANTA BAIXA, COBERTURA, CORTES A-A' E B-B' COM VOLUME PROTEGIDO | G26: 1 | H26: 0 | I26: 44136
A27: K19-204-FER-DE-023 | B27: MG20210510899 | C27: Britagem | D27: PROJETO EXECUTIVO DO SISTEMA DE PROTEÇÃO CONTRA DESCARGAS ATMOSFÉRICAS (SPDA) | E27: BRITAGEM | F27: PLANTA BAIXA, COBERTURA E CORTE A-A' COM VOLUME PROTEGIDO | G27: 1 | H27: 0 | I27: 44136
A28: K19-204-FER-DE-024 | C28: Filtragem Cerâmica de Concentrado | D28: PROJETO EXECUTIVO DO SISTEMA DE PROTEÇÃO CONTRA DESCARGAS ATMOSFÉRICAS (SPDA) | E28: FILTRAGEM CERÂMICA DE CONCENTRADO | F28: PLANTA BAIXA, COBERTURA E CORTE A-A' COM VOLUME PROTEGIDO | G28: 1 | H28: 0 | I28: 44136
A29: K19-204-FER-DE-025 | C29: Planta Piloto ITM | D29: PROJETO EXECUTIVO DO SISTEMA DE PROTEÇÃO CONTRA DESCARGAS ATMOSFÉRICAS (SPDA) | E29: PLANTA PILOTO ITM | F29: PLANTA BAIXA, COBERTURA E CORTE A-A' COM VOLUME PROTEGIDO | G29: 1 | H29: 0 | I29: 44136
A30: K19-204-FER-DE-026 | C30: Fábrica de Placas e Container Meio Ambiente | D30: PROJETO EXECUTIVO DO SISTEMA DE PROTEÇÃO CONTRA DESCARGAS ATMOSFÉRICAS (SPDA) | E30: FÁBRICA DE PLACAS E CONTAINER MEIO AMBIENTE | F30: PLANTA BAIXA, COBERTURA, CORTES A-A' E B-B' COM VOLUME PROTEGIDO | G30: 1 | H30: 0 | I30: 44136
A31: K19-204-FER-DE-027 | C31: Portaria 2 | D31: PROJETO EXECUTIVO DO SISTEMA DE PROTEÇÃO CONTRA DESCARGAS ATMOSFÉRICAS (SPDA) | E31: PORTARIA 2 | F31: PLANTA BAIXA, COBERTURA E CORTE A-A' COM VOLUME PROTEGIDO | G31: 1 | H31: 0 | I31: 44136
A32: K19-204-FER-DE-028 | C32: Poço Artesiano 1 | D32: PROJETO EXECUTIVO DO SISTEMA DE PROTEÇÃO CONTRA DESCARGAS ATMOSFÉRICAS (SPDA) | E32: POÇO ARTESIANO 1 | F32: PLANTA BAIXA, COBERTURA E CORTE A A' COM VOLUME PROTEGIDO | G32: 1 | H32: 0 | I32: 44136
A33: K19-204-FER-DE-029 | C33: Apanhador de Água | D33: PROJETO EXECUTIVO DO SISTEMA DE PROTEÇÃO CONTRA DESCARGAS ATMOSFÉRICAS (SPDA) | E33: APANHADOR DE ÁGUA | F33: PLANTA BAIXA, COBERTURA E CORTE A-A' COM VOLUME PROTEGIDO | G33: 1 | H33: 0 | I33: 44136
A34: K19-204-FER-DE-030 | C34: Smartmine e Operação Mina | D34: PROJETO EXECUTIVO DO SISTEMA DE PROTEÇÃO CONTRA DESCARGAS ATMOSFÉRICAS (SPDA) | E34: SMARTMINE E OPERAÇÃO MINA | F34: PLANTA BAIXA, COBERTURA, CORTES A-A' E B-B' COM VOLUME PROTEGIDO | G34: 1 | H34: 0 | I34: 44136
A35: K19-204-FER-DE-031 | C35: Tenda Almoxarifado | D35: PROJETO EXECUTIVO DO SISTEMA DE PROTEÇÃO CONTRA DESCARGAS ATMOSFÉRICAS (SPDA) | E35: TENDA ALMOXARIFADO | F35: PLANTA BAIXA, COBERTURA, CORTES A-A' E B-B' COM VOLUME PROTEGIDO | G35: 1 | H35: 0 | I35: 44136
A36: K19-204-FER-DE-032 | C36: Oficina de Equipamentos | D36: PROJETO EXECUTIVO DO SISTEMA DE PROTEÇÃO CONTRA DESCARGAS ATMOSFÉRICAS (SPDA) | E36: OFICINA DE EQUIPAMENTOS | F36: PLANTA BAIXA, COBERTURA, CORTE A-A' E VOLUME PROTEGIDO B-B' | G36: 1 | H36: 0 | I36: 44136
A37: K19-204-FER-DE-033 | C37: Posto de Combustível | D37: PROJETO EXECUTIVO DO SISTEMA DE PROTEÇÃO CONTRA DESCARGAS ATMOSFÉRICAS (SPDA) | E37: POSTO DE COMBUSTÍVEL | F37: PLANTA BAIXA, COBERTURA, CORTES A-A' E B-B' COM VOLUME PROTEGIDO | G37: 1 | H37: 0 | I37: 44136
A38: K19-204-FER-DE-034 | C38: Depósito de Resíduos | D38: PROJETO EXECUTIVO DO SISTEMA DE PROTEÇÃO CONTRA DESCARGAS ATMOSFÉRICAS (SPDA) | E38: DEPÓSITO DE RESÍDUOS | F38: PLANTA BAIXA, COBERTURA, CORTES A-A' E B-B' COM VOLUME PROTEGIDO | G38: 1 | H38: 0 | I38: 44136
A39: K19-204-FER-DE-035 | C39: Depósito de Produtos Químicos | G39: 1 | H39: 1 | I39: 44136
A40: K19-204-FER-DE-036 | C40: Peneiras Cava sul | D40: PROJETO EXECUTIVO DO SISTEMA DE PROTEÇÃO CONTRA DESCARGAS ATMOSFÉRICAS (SPDA) | E40: CANTEIRO DE OBRAS CONTRATADAS VMF | F40: PLANTA BAIXA, COBERTURA, CORTE A-A' E CORTE B-B' COM VOLUME PROTEGIDO | G40: 1 | H40: 0 | I40: 44166
A41: K19-204-FER-DE-037 | B41: MG20210427181 | C41: Nova ETE Oficina | D41: PROJETO EXECUTIVO DO SISTEMA DE PROTEÇÃO CONTRA DESCARGAS ATMOSFÉRICAS (SPDA) | E41: NOVA ETE OFICINA | F41: PLANTA BAIXA, COBERTURA, CORTES A-A' E B-B' | G41: 1 | H41: 0 | I41: 44136
A42: K19-204-FER-DE-038 | B42: MG20210510720 | C42: Nova ETE Principal | D42: PROJETO EXECUTIVO DO SISTEMA DE PROTEÇÃO CONTRA DESCARGAS ATMOSFÉRICAS (SPDA) | E42: NOVA ETE PRINCIPAL | F42: PLANTA BAIXA, COBERTURA, CORTES A-A' E B-B' | G42: 1 | H42: 0 | I42: 44136
A43: K19-204-FER-DE-039 | B43: MG20210510928 | C43: Novo DIR (Depósito Intermediário de Resíduos) | D43: PROJETO EXECUTIVO DO SISTEMA DE PROTEÇÃO CONTRA DESCARGAS ATMOSFÉRICAS (SPDA) | E43: NOVO DIR (DEPÓSITO INTERMEDIÁRIO DE RESÍDUOS) | F43: PLANTA BAIXA, COBERTURA, CORTES A-A', B-B' E C-C' COM VOLUME PROTEGIDO | G43: 1 | H43: 0 | I43: 44136
A44: K19-204-FER-DE-040 | B44: MG20210427221 | C44: Canteiro de obras contratadas VMF | D44: PROJETO EXECUTIVO DO SISTEMA DE PROTEÇÃO CONTRA DESCARGAS ATMOSFÉRICAS (SPDA) | E44: CANTEIRO DE OBRAS CONTRATADAS VMF | F44: PLANTA BAIXA, COBERTURA, CORTES A-A', B-B' E C-C' COM VOLUME PROTEGIDO | G44: 1 | H44: 0 | I44: 44166
A45: K19-204-FER-DE-041 | B45: MG20210510983 | C45: Mirante | D45: PROJETO EXECUTIVO DO SISTEMA DE PROTEÇÃO CONTRA DESCARGAS ATMOSFÉRICAS (SPDA) | E45: MIRANTE | F45: PLANTA BAIXA, COBERTURA, CORTES A-A', B-B' E C-C' COM VOLUME PROTEGIDO | G45: 1 | H45: 0 | I45: 44197
...

Sheet MDs
C1: Ferro+ - Ferro+ Mineração S.A
C2: CONTRATO: 089/2026 - Empresa: MSI Engenharia e Tecnologia LTDA
A3: Número | B3: ART | C3: Descrição da Área | E3: Título 2 | F3: Título 4 | G3: Título 5 | H3: Título 6 | I3: Revisão | J3: Data de Emissão | K3: Número MSI | L3: Número J.Mendes
A4: K19-204-FER-MD-001 | B4: 6140344 | C4: Planta Moinho de Rolos | D4: PROJETO EXECUTIVO | E4: FERRO+ MINERAÇÃO S.A | F4: PLANTA MOINHO DE ROLOS | G4: SPDA / ATERRAMENTO | H4: MEMORIAL DESCRITIVO DO PROJETO DE SPDA | I4: 0 | J4: 44075
A5: K19-204-FER-MD-002 | C5: Container Gestão de Contratos | D5: PROJETO EXECUTIVO | E5: FERRO+ MINERAÇÃO S.A | F5: CONTAINER GESTÃO DE CONTRATOS | G5: SPDA / ATERRAMENTO | H5: MEMORIAL DESCRITIVO DO PROJETO DE SPDA | I5: 0 | J5: 44075
A6: K19-204-FER-MD-003 | C6: Container RH Portaria | D6: PROJETO EXECUTIVO | E6: FERRO+ MINERAÇÃO S.A | F6: CONTAINER RH PORTARIA | G6: SPDA / ATERRAMENTO | H6: MEMORIAL DESCRITIVO DO PROJETO DE SPDA | I6: 0 | J6: 44075
A7: K19-204-FER-MD-004 | C7: Container RH Restaurante | D7: PROJETO EXECUTIVO | E7: FERRO+ MINERAÇÃO S.A | F7: CONTAINER RH RESTAURANTE | G7: SPDA / ATERRAMENTO | H7: MEMORIAL DESCRITIVO DO PROJETO DE SPDA | I7: 0 | J7: 44075
A8: K19-204-FER-MD-005 | C8: Container Fiscal Portaria | D8: PROJETO EXECUTIVO | E8: FERRO+ MINERAÇÃO S.A | F8: CONTAINER FISCAL PORTARIA | G8: SPDA / ATERRAMENTO | H8: MEMORIAL DESCRITIVO DO PROJETO DE SPDA | I8: 0 | J8: 44075
A9: K19-204-FER-MD-006 | C9: Container da Parada de Segurança | D9: PROJETO EXECUTIVO | E9: FERRO+ MINERAÇÃO S.A | F9: CONTAINER DA PARADA DE SEGURANÇA | G9: SPDA / ATERRAMENTO | H9: MEMORIAL DESCRITIVO DO PROJETO DE SPDA | I9: 0 | J9: 44075
A10: K19-204-FER-MD-007 | C10: Container Geotecnia | D10: PROJETO EXECUTIVO | E10: FERRO+ MINERAÇÃO S.A | F10: CONTAINER GEOTECNIA | G10: SPDA / ATERRAMENTO | H10: MEMORIAL DESCRITIVO DO PROJETO DE SPDA | I10: 0 | J10: 44075
A11: K19-204-FER-MD-008 | C11: Containers próximo a Planta Piloto ITM | D11: PROJETO EXECUTIVO | E11: FERRO+ MINERAÇÃO S.A | F11: CONTAINERS PRÓXIMO A PLANTA PILOTO ITM | G11: SPDA / ATERRAMENTO | H11: MEMORIAL DESCRITIVO DO PROJETO DE SPDA | I11: 0 | J11: 44075
A12: K19-204-FER-MD-009 | C12: Escritório Geologia/Geotecnia | D12: PROJETO EXECUTIVO | E12: FERRO+ MINERAÇÃO S.A | F12: ESCRITÓRIO GEOLOGIA/GEOTECNIA | G12: SPDA / ATERRAMENTO | H12: MEMORIAL DESCRITIVO DO PROJETO DE SPDA | I12: 0 | J12: 44075
A13: K19-204-FER-MD-010 | C13: Oficina Caldeiraria | D13: PROJETO EXECUTIVO | E13: FERRO+ MINERAÇÃO S.A | F13: OFICINA CALDEIRARIA | G13: SPDA / ATERRAMENTO | H13: MEMORIAL DESCRITIVO DO PROJETO DE SPDA | I13: 0 | J13: 44075
A14: K19-204-FER-MD-011 | C14: Tanque Ácido Filtragem | D14: PROJETO EXECUTIVO | E14: FERRO+ MINERAÇÃO S.A | F14: TANQUE ÁCIDO FILTRAGEM | G14: SPDA / ATERRAMENTO | H14: MEMORIAL DESCRITIVO DO PROJETO DE SPDA | I14: 0 | J14: 44075
A15: K19-204-FER-MD-012 | C15: Peneira Estática Mina | D15: PROJETO EXECUTIVO | E15: FERRO+ MINERAÇÃO S.A | F15: PENEIRA ESTÁTICA MINA | G15: SPDA / ATERRAMENTO | H15: MEMORIAL DESCRITIVO DO PROJETO DE SPDA | I15: 0 | J15: 44075
A16: K19-204-FER-MD-013 | C16: Área de Containers Contratadas | D16: PROJETO EXECUTIVO | E16: FERRO+ MINERAÇÃO S.A | F16: ÁREA DE CONTAINERS CONTRATADAS | G16: SPDA / ATERRAMENTO | H16: MEMORIAL DESCRITIVO DO PROJETO DE SPDA | I16: 0 | J16: 44075
... A23: K19-204-FER-MD-020 | C23: Ponto de Ônibus | D23: PROJETO EXECUTIVO | E23: FERRO+ MINERAÇÃO S.A | F23: PONTO DE ÔNIBUS | G23: SPDA / ATERRAMENTO | H23: MEMORIAL DESCRITIVO DO PROJETO DE SPDA | I23: 0 | J23: 44075
A24: K19-204-FER-MD-021 | B24: MG20210510755 | C24: Rebritagens 1 e 2, Espirais e SE 138kV/CCM | D24: PROJETO EXECUTIVO | E24: FERRO+ MINERAÇÃO S.A | F24: REBRITAGENS 1 E 2, ESPIRAIS E SE 138KV/CCM | G24: SPDA / ATERRAMENTO | H24: MEMORIAL DESCRITIVO DO PROJETO DE SPDA | I24: 0 | J24: 44136
A25: K19-204-FER-MD-022 | C25: Separador Magnético, Floculantes e Espessadores | D25: PROJETO EXECUTIVO | E25: FERRO+ MINERAÇÃO S.A | F25: SEPARADOR MAGNÉTICO, FLOCULANTES E ESPESSADORES | G25: SPDA / ATERRAMENTO | H25: MEMORIAL DESCRITIVO DO PROJETO DE SPDA | I25: 0 | J25: 44136
A26: K19-204-FER-MD-023 | B26: MG20210510899 | C26: Britagem | D26: PROJETO EXECUTIVO | E26: FERRO+ MINERAÇÃO S.A | F26: BRITAGEM | G26: SPDA / ATERRAMENTO | H26: MEMORIAL DESCRITIVO DO PROJETO DE SPDA | I26: 0 | J26: 44136
A27: K19-204-FER-MD-024 | C27: Filtragem Cerâmica de Concentrado | D27: PROJETO EXECUTIVO | E27: FERRO+ MINERAÇÃO S.A | F27: FILTRAGEM CERÂMICA DE CONCENTRADO | G27: SPDA / ATERRAMENTO | H27: MEMORIAL DESCRITIVO DO PROJETO DE SPDA | I27: 0 | J27: 44136
A28: K19-204-FER-MD-025 | C28: Planta Piloto ITM | D28: PROJETO EXECUTIVO | E28: FERRO+ MINERAÇÃO S.A | F28: PLANTA PILOTO ITM | G28: SPDA / ATERRAMENTO | H28: MEMORIAL DESCRITIVO DO PROJETO DE SPDA | I28: 0 | J28: 44136
A29: K19-204-FER-MD-026 | C29: Fábrica de Placas e Container Meio Ambiente | D29: PROJETO EXECUTIVO | E29: FERRO+ MINERAÇÃO S.A | F29: FÁBRICA DE PLACAS E CONTAINER MEIO AMBIENTE | G29: SPDA / ATERRAMENTO | H29: MEMORIAL DESCRITIVO DO PROJETO DE SPDA | I29: 0 | J29: 44136
A30: K19-204-FER-MD-027 | C30: Portaria 2 | D30: PROJETO EXECUTIVO | E30: FERRO+ MINERAÇÃO S.A | F30: PORTARIA 2 | G30: SPDA / ATERRAMENTO | H30: MEMORIAL DESCRITIVO DO PROJETO DE SPDA | I30: 0 | J30: 44136
A31: K19-204-FER-MD-028 | C31: Poço Artesiano | D31: PROJETO EXECUTIVO | E31: FERRO+ MINERAÇÃO S.A | F31: POÇO ARTESIANO | G31: SPDA / ATERRAMENTO | H31: MEMORIAL DESCRITIVO DO PROJETO DE SPDA | I31: 0 | J31: 44136
A32: K19-204-FER-MD-029 | C32: Apanhador de Água do Poço 3 | D32: PROJETO EXECUTIVO | E32: FERRO+ MINERAÇÃO S.A | F32: APANHADOR DE ÁGUA DO POÇO 3 | G32: SPDA / ATERRAMENTO | H32: MEMORIAL DESCRITIVO DO PROJETO DE SPDA | I32: 0 | J32: 44136
A33: K19-204-FER-MD-030 | C33: Smartmine e Operação Mina | D33: PROJETO EXECUTIVO | E33: FERRO+ MINERAÇÃO S.A | F33: SMARTMINE E OPERAÇÃO MINA | G33: SPDA / ATERRAMENTO | H33: MEMORIAL DESCRITIVO DO PROJETO DE SPDA | I33: 0 | J33: 44136
A34: K19-204-FER-MD-031 | C34: Tenda Almoxarifado | D34: PROJETO EXECUTIVO | E34: FERRO+ MINERAÇÃO S.A | F34: TENDA ALMOXARIFADO | G34: SPDA / ATERRAMENTO | H34: MEMORIAL DESCRITIVO DO PROJETO DE SPDA | I34: 0 | J34: 44136
A35: K19-204-FER-MD-032 | C35: Oficina de Equipamentos | D35: PROJETO EXECUTIVO | E35: FERRO+ MINERAÇÃO S.A | F35: OFICINA DE EQUIPAMENTOS | G35: SPDA / ATERRAMENTO | H35: MEMORIAL DESCRITIVO DO PROJETO DE SPDA | I35: 0 | J35: 44136
A36: K19-204-FER-MD-033 | C36: Posto de Combustível | D36: PROJETO EXECUTIVO | E36: FERRO+ MINERAÇÃO S.A | F36: POSTO DE COMBUSTÍVEL | G36: SPDA / ATERRAMENTO | H36: MEMORIAL DESCRITIVO DO PROJETO DE SPDA | I36: 0 | J36: 44136
A37: K19-204-FER-MD-034 | C37: Depósito de Resíduos | D37: PROJETO EXECUTIVO | E37: FERRO+ MINERAÇÃO S.A | F37: DEPÓSITO DE RESÍDUOS | G37: SPDA / ATERRAMENTO | H37: MEMORIAL DESCRITIVO DO PROJETO DE SPDA | I37: 0 | J37: 44136
A38: K19-204-FER-MD-035 | C38: Depósito de Produtos Químicos | D38: PROJETO EXECUTIVO | E38: FERRO+ MINERAÇÃO S.A | F38: DEPÓSITO DE PRODUTOS QUÍMICOS | G38: SPDA / ATERRAMENTO | H38: MEMORIAL DESCRITIVO DO PROJETO DE SPDA | I38: 1 | J38: 44136
A39: K19-204-FER-MD-036 | B39: 20210369268 | C39: Peneiras Cava Sul | D39: PROJETO EXECUTIVO | E39: FERRO+ MINERAÇÃO S.A | F39: PENEIRAS CAVA SUL | G39: SPDA / ATERRAMENTO | H39: MEMORIAL DESCRITIVO DO PROJETO DE SPDA | I39: 0 | J39: 44136
A40: K19-204-FER-MD-037 | B40: MG202101427181 | C40: Nova ETE Oficina | D40: PROJETO EXECUTIVO | E40: FERRO+ MINERAÇÃO S.A | F40: NOVA ETE OFICINA | G40: SPDA / ATERRAMENTO | H40: MEMORIAL DESCRITIVO DO PROJETO DE SPDA | I40: 0 | J40: 44136
A41: K19-204-FER-MD-038 | B41: MG20210510720 | C41: Nova ETE Principal | D41: PROJETO EXECUTIVO | E41: FERRO+ MINERAÇÃO S.A | F41: NOVA ETE PRINCIPAL | G41: SPDA / ATERRAMENTO | H41: MEMORIAL DESCRITIVO DO PROJETO DE SPDA | I41: 0 | J41: 44136
A42: K19-204-FER-MD-039 | B42: MG20210510928 | C42: Novo DIR (Depósito Intermediário de Resíduos) | D42: PROJETO EXECUTIVO | E42: FERRO+ MINERAÇÃO S.A | F42: NOVO DIR (DEPÓSITO INTERMEDIÁRIO DE RESÍDUOS) | G42: SPDA / ATERRAMENTO | H42: MEMORIAL DESCRITIVO DO PROJETO DE SPDA | I42: 0 | J42: 44136
A43: K19-204-FER-MD-040 | B43: MG202101427221 | C43: Canteiro de Obras Contratadas VMF | D43: PROJETO EXECUTIVO | E43: FERRO+ MINERAÇÃO S.A | F43: CANTEIRO DE OBRAS CONTRATADAS VMF | G43: SPDA / ATERRAMENTO | H43: MEMORIAL DESCRITIVO DO PROJETO DE SPDA | I43: 0 | J43: 44166
A44: K19-204-FER-MD-041 | B44: MG20210510983 | C44: Mirante | D44: PROJETO EXECUTIVO | E44: FERRO+ MINERAÇÃO S.A | F44: MIRANTE | G44: SPDA / ATERRAMENTO | H44: MEMORIAL DESCRITIVO DO PROJETO DE SPDA | I44: 0 | J44: 44197
A45: K19-204-FER-MD-042 | B45: MG202101427245 | C45: Container Recepção da Portaria | D45: PROJETO EXECUTIVO | E45: FERRO+ MINERAÇÃO S.A | F45: CONTAINER RECEPÇÃO PORTARIA | G45: SPDA / ATERRAMENTO | H45: MEMORIAL DESCRITIVO DO PROJETO DE SPDA | I45: 0 | J45: 44287
A46: K19-204-FER-MD-043 | B46: 6492312 | C46: Patio Contratadas | D46: PROJETO EXECUTIVO | E46: FERRO+ MINERAÇÃO S.A | F46: PATIO CONTRATADAS | G46: SPDA / ATERRAMENTO | H46: MEMORIAL DESCRITIVO DO PROJETO DE SPDA | I46: 0 | J46: 44896
...

Sheet LMs
C1: Ferro+ - Ferro+ Mineração S.A
C2: CONTRATO: 089/2026 - Empresa: MSI Engenharia e Tecnologia LTDA
A3: Número | B3: Obs.: | C3: Descrição da Área | D3: Título 1 | E3: Título 2 | F3: Título 4 | G3: Título 5 | H3: Título 6 | I3: Revisão | J3: Data de Emissão | K3: Número MSI | L3: Número J.Mendes
A4: K19-204-FER-LM-001 | B4: 6140344 | C4: Planta Moinho de Rolos | D4: PROJETO EXECUTIVO | E4: FERRO+ MINERAÇÃO S.A | F4: PLANTA MOINHO DE ROLOS | G4: SPDA / ATERRAMENTO | H4: LISTA DE MATERIAIS DO PROJETO DE SPDA | I4: 0 | J4: 44075
A5: K19-204-FER-LM-002 | C5: Container Gestão de Contratos | D5: PROJETO EXECUTIVO | E5: FERRO+ MINERAÇÃO S.A | F5: CONTAINER GESTÃO DE CONTRATOS | G5: SPDA / ATERRAMENTO | H5: LISTA DE MATERIAIS DO PROJETO DE SPDA | I5: 0 | J5: 44075
A6: K19-204-FER-LM-003 | C6: Container RH Portaria | D6: PROJETO EXECUTIVO | E6: FERRO+ MINERAÇÃO S.A | F6: CONTAINER RH PORTARIA | G6: SPDA / ATERRAMENTO | H6: LISTA DE MATERIAIS DO PROJETO DE SPDA | I6: 0 | J6: 44075
A7: K19-204-FER-LM-004 | C7: Container RH Restaurante | D7: PROJETO EXECUTIVO | E7: FERRO+ MINERAÇÃO S.A | F7: CONTAINER RH RESTAURANTE | G7: SPDA / ATERRAMENTO | H7: LISTA DE MATERIAIS DO PROJETO DE SPDA | I7: 0 | J7: 44075
A8: K19-204-FER-LM-005 | C8: Container Fiscal Portaria | D8: PROJETO EXECUTIVO | E8: FERRO+ MINERAÇÃO S.A | F8: CONTAINER FISCAL PORTARIA | G8: SPDA / ATERRAMENTO | H8: LISTA DE MATERIAIS DO PROJETO DE SPDA | I8: 0 | J8: 44075
A9: K19-204-FER-LM-006 | C9: Container da Parada de Segurança | D9: PROJETO EXECUTIVO | E9: FERRO+ MINERAÇÃO S.A | F9: CONTAINER DA PARADA DE SEGURANÇA | G9: SPDA / ATERRAMENTO | H9: LISTA DE MATERIAIS DO PROJETO DE SPDA | I9: 0 | J9: 44075
A10: K19-204-FER-LM-007 | C10: Container da Geotecnica | D10: PROJETO EXECUTIVO | E10: FERRO+ MINERAÇÃO S.A | F10: CONTAINER DA GEOTECNICA | G10: SPDA / ATERRAMENTO | H10: LISTA DE MATERIAIS DO PROJETO DE SPDA | I10: 0 | J10: 44075
A11: K19-204-FER-LM-008 | C11: Containers Próximo a Planta Piloto | D11: PROJETO EXECUTIVO | E11: FERRO+ MINERAÇÃO S.A | F11: CONTAINERS PRÓXIMO A PLANTA PILOTO | G11: SPDA / ATERRAMENTO | H11: LISTA DE MATERIAIS DO PROJETO DE SPDA | I11: 0 | J11: 44075
A12: K19-204-FER-LM-009 | C12: Escritório - Geologia/Geologia | D12: PROJETO EXECUTIVO | E12: FERRO+ MINERAÇÃO S.A | F12: ESCRITÓRIO GEOLOGIA/GEOLOGIA | G12: SPDA / ATERRAMENTO | H12: LISTA DE MATERIAIS DO PROJETO DE SPDA | I12: 0 | J12: 44075
A13: K19-204-FER-LM-010 | C13: Oficina Caldeiraria | D13: PROJETO EXECUTIVO | E13: FERRO+ MINERAÇÃO S.A | F13: OFICINA CALDEIRARIA | G13: SPDA / ATERRAMENTO | H13: LISTA DE MATERIAIS DO PROJETO DE SPDA | I13: 0 | J13: 44075
A14: K19-204-FER-LM-011 | C14: Tanque Ácido Filtragem | D14: PROJETO EXECUTIVO | E14: FERRO+ MINERAÇÃO S.A | F14: TANQUE ÁCIDO FILTRAGEM | G14: SPDA / ATERRAMENTO | H14: LISTA DE MATERIAIS DO PROJETO DE SPDA | I14: 0 | J14: 44075
A15: K19-204-FER-LM-012 | C15: Peneira Estática Mina | D15: PROJETO EXECUTIVO | E15: FERRO+ MINERAÇÃO S.A | F15: PENEIRA ESTÁTICA MINA | G15: SPDA / ATERRAMENTO | H15: LISTA DE MATERIAIS DO PROJETO DE SPDA | I15: 0 | J15: 44075
A16: K19-204-FER-LM-013 | C16: Área de Canteiros de Obras | D16: PROJETO EXECUTIVO | E16: FERRO+ MINERAÇÃO S.A | F16: ÁREA DE CANTEIROS DE OBRAS | G16: SPDA / ATERRAMENTO | H16: LISTA DE MATERIAIS DO PROJETO DE SPDA | I16: 0 | J16: 44075
... A23: K19-204-FER-LM-020 | C23: Ponto de Ônibus ITM | D23: PROJETO EXECUTIVO | E23: FERRO+ MINERAÇÃO S.A | F23: PONTO DE ÔNIBUS ITM | G23: SPDA / ATERRAMENTO | H23: LISTA DE MATERIAIS DO PROJETO DE SPDA | I23: 0 | J23: 44075
A24: K19-204-FER-LM-021 | B24: MG20210510755 | C24: Classificação, Rebritagens 1 e 2, Espirais e Subestação 138KV - CCM | D24: PROJETO EXECUTIVO | E24: FERRO+ MINERAÇÃO S.A | F24: CLASSIFICAÇÃO, REBRITAGENS 1 E 2, ESPIRAIS E SUBESTAÇÃO 138KV - CCM | G24: SPDA / ATERRAMENTO | H24: LISTA DE MATERIAIS DO PROJETO DE SPDA | I24: 1 | J24: 44136
A25: K19-204-FER-LM-022 | C25: Separador Magnético, Floculantes e Espessadores | D25: PROJETO EXECUTIVO | E25: FERRO+ MINERAÇÃO S.A | F25: SEPARADOR MAGNÉTICO, FLOCULANTES E ESPESSADORES | G25: SPDA / ATERRAMENTO | H25: LISTA DE MATERIAIS DO PROJETO DE SPDA | I25: 1 | J25: 44136
A26: K19-204-FER-LM-023 | B26: MG20210510899 | C26: Britagem | D26: PROJETO EXECUTIVO | E26: FERRO+ MINERAÇÃO S.A | F26: BRITAGEM | G26: SPDA / ATERRAMENTO | H26: LISTA DE MATERIAIS DO PROJETO DE SPDA | I26: 1 | J26: 44136
A27: K19-204-FER-LM-024 | C27: Filtragem Cerâmica de Concentrado | D27: PROJETO EXECUTIVO | E27: FERRO+ MINERAÇÃO S.A | F27: FILTRAGEM CERÂMICA DE CONCENTRADO | G27: SPDA / ATERRAMENTO | H27: LISTA DE MATERIAIS DO PROJETO DE SPDA | I27: 1 | J27: 44136
A28: K19-204-FER-LM-025 | C28: Planta Piloto ITM | D28: PROJETO EXECUTIVO | E28: FERRO+ MINERAÇÃO S.A | F28: PLANTA PILOTO ITM | G28: SPDA / ATERRAMENTO | H28: LISTA DE MATERIAIS DO PROJETO DE SPDA | I28: 1 | J28: 44136
A29: K19-204-FER-LM-026 | C29: Fábrica de Placas e Container Meio Ambiente | D29: PROJETO EXECUTIVO | E29: FERRO+ MINERAÇÃO S.A | F29: FÁBRICA DE PLACAS E CONTAINER MEIO AMBIENTE | G29: SPDA / ATERRAMENTO | H29: LISTA DE MATERIAIS DO PROJETO DE SPDA | I29: 1 | J29: 44136
A30: K19-204-FER-LM-027 | C30: Portaria 2 | D30: PROJETO EXECUTIVO | E30: FERRO+ MINERAÇÃO S.A | F30: PORTARIA 2 | G30: SPDA / ATERRAMENTO | H30: LISTA DE MATERIAIS DO PROJETO DE SPDA | I30: 0 | J30: 44136
A31: K19-204-FER-LM-028 | C31: Poço Artesiano 1 | D31: PROJETO EXECUTIVO | E31: FERRO+ MINERAÇÃO S.A | F31: POÇO ARTESIANO 1 | G31: SPDA / ATERRAMENTO | H31: LISTA DE MATERIAIS DO PROJETO DE SPDA | I31: 0 | J31: 44136
A32: K19-204-FER-LM-029 | C32: Apanhador de Água do Poço 3 | D32: PROJETO EXECUTIVO | E32: FERRO+ MINERAÇÃO S.A | F32: APANHADOR DE ÁGUA DO POÇO 3 | G32: SPDA / ATERRAMENTO | H32: LISTA DE MATERIAIS DO PROJETO DE SPDA | I32: 0 | J32: 44136
A33: K19-204-FER-LM-030 | C33: Smartmine e Operação Mina | D33: PROJETO EXECUTIVO | E33: FERRO+ MINERAÇÃO S.A | F33: SMARTMINE E OPERAÇÃO MINA | G33: SPDA / ATERRAMENTO | H33: LISTA DE MATERIAIS DO PROJETO DE SPDA | I33: 0 | J33: 44136
A34: K19-204-FER-LM-031 | C34: Tenda Almoxarifado | D34: PROJETO EXECUTIVO | E34: FERRO+ MINERAÇÃO S.A | F34: TENDA ALMOXARIFADO | G34: SPDA / ATERRAMENTO | H34: LISTA DE MATERIAIS DO PROJETO DE SPDA | I34: 0 | J34: 44136
A35: K19-204-FER-LM-032 | C35: Oficina de Equipamentos | D35: PROJETO EXECUTIVO | E35: FERRO+ MINERAÇÃO S.A | F35: OFICINA DE EQUIPAMENTOS | G35: SPDA / ATERRAMENTO | H35: LISTA DE MATERIAIS DO PROJETO DE SPDA | I35: 1 | J35: 44136
A36: K19-204-FER-LM-033 | C36: Posto de Combustível | D36: PROJETO EXECUTIVO | E36: FERRO+ MINERAÇÃO S.A | F36: POSTO DE COMBUSTÍVEL | G36: SPDA / ATERRAMENTO | H36: LISTA DE MATERIAIS DO PROJETO DE SPDA | I36: 1 | J36: 44136
A37: K19-204-FER-LM-034 | C37: Depósito de Resíduos | D37: PROJETO EXECUTIVO | E37: FERRO+ MINERAÇÃO S.A | F37: DEPÓSITO DE RESÍDUOS | G37: SPDA / ATERRAMENTO | H37: LISTA DE MATERIAIS DO PROJETO DE SPDA | I37: 0 | J37: 44136
A38: K19-204-FER-LM-035 | C38: Depósito de Produtos Químicos | D38: PROJETO EXECUTIVO | E38: FERRO+ MINERAÇÃO S.A | F38: DEPÓSITO DE PRODUTOS QUÍMICOS | G38: SPDA / ATERRAMENTO | H38: LISTA DE MATERIAIS DO PROJETO DE SPDA | I38: 1 | J38: 44136
A39: K19-204-FER-LM-036 | B39: 20210369268 | C39: Peneiras Cava Sul | D39: PROJETO EXECUTIVO | E39: FERRO+ MINERAÇÃO S.A | F39: PENEIRAS CAVA SUL | G39: SPDA / ATERRAMENTO | H39: LISTA DE MATERIAIS DO PROJETO DE SPDA | I39: 1 | J39: 44136
A40: K19-204-FER-LM-037 | B40: MG202101427181 | C40: Nova ETE Oficina | D40: PROJETO EXECUTIVO | E40: FERRO+ MINERAÇÃO S.A
A41: K19-204-FER-LM-038 | B41: MG20210510720 | C41: Nova ETE Principal | D41: PROJETO EXECUTIVO | E41: FERRO+ MINERAÇÃO S.A | F41: NOVA ETE PRINCIPAL | G41: SPDA / ATERRAMENTO | H41: LISTA DE MATERIAIS DO PROJETO DE SPDA | I41: 0 | J41: 44136
A42: K19-204-FER-LM-039 | B42: MG20210510928 | C42: Novo DIR (Depósito Intermediário de Resíduos) | D42: PROJETO EXECUTIVO | E42: FERRO+ MINERAÇÃO S.A | F42: NOVO DIR (DEPÓSITO INTERMEDIÁRIO DE RESÍDUOS) | G42: SPDA / ATERRAMENTO | H42: LISTA DE MATERIAIS DO PROJETO DE SPDA | I42: 0 | J42: 44136
A43: K19-204-FER-LM-040 | B43: MG202101427221 | C43: Canteiro de Obra Contratadas VMF | D43: PROJETO EXECUTIVO | E43: FERRO+ MINERAÇÃO S.A | F43: CANTEIRO DE OBRAS CONTRATADAS VMF | G43: SPDA / ATERRAMENTO | H43: LISTA DE MATERIAIS DO PROJETO DE SPDA | I43: 0 | J43: 44166
A44: K19-204-FER-LM-041 | B44: MG20210510983 | C44: Mirante | D44: PROJETO EXECUTIVO | E44: FERRO+ MINERAÇÃO S.A | F44: MIRANTE | G44: SPDA / ATERRAMENTO | H44: LISTA DE MATERIAIS DO PROJETO DE SPDA | I44: 0 | J44: 44197
A45: K19-204-FER-LM-042 | B45: MG202101427245 | C45: Container Recepção da Portaria | D45: PROJETO EXECUTIVO | E45: FERRO+ MINERAÇÃO S.A | F45: CONTAINER RECEPÇÃO DA PORTARIA | G45: SPDA / ATERRAMENTO | H45: LISTA DE MATERIAIS DO PROJETO DE SPDA | I45: 0
A46: K19-204-FER-LM-043 | B46: 6492312 | C46: Pátio Contratadas | D46: PROJETO EXECUTIVO | E46: FERRO+ MINERAÇÃO S.A | F46: PÁTIO CONTRATADAS | G46: SPDA / ATERRAMENTO | H46: LISTA DE MATERIAIS DO PROJETO DE SPDA | I46: 0 | J46: 44409
...

Sheet MCs
C1: Ferro+ - Ferro+ Mineração S.A
C2: CONTRATO: 089/2026 - Empresa: MSI Engenharia e Tecnologia LTDA
A3: Número | B3: Obs.: | C3: Descrição da Área | D3: Título 1 | E3: Título 2 | F3: Título 3 | G3: Título 4 | H3: Título 5 | I3: Revisão | J3: Data de Emissão | K3: Número MSI | L3: Número J.Mendes
A4: K19-204-FER-MC-001 | C4: Classificação | D4: PROJETO BASICO | E4: FERRO+ MINERAÇÃO S.A | F4: CLASSIFICAÇÃO | G4: SPDA / ATERRAMENTO | H4: ANÁLISE DE RISCO DO PROJETO DE SPDA | I4: 0 | J4: 44136
A5: K19-204-FER-MC-002 | C5: Separação Magnética | D5: PROJETO BASICO | E5: FERRO+ MINERAÇÃO S.A | F5: SEPARAÇÃO MAGNÉTICA | G5: SPDA / ATERRAMENTO | H5: ANÁLISE DE RISCO DO PROJETO DE SPDA | I5: 0 | J5: 44136
A6: K19-204-FER-MC-003 | C6: Britagem | D6: PROJETO BASICO | E6: FERRO+ MINERAÇÃO S.A | F6: BRITAGEM | G6: SPDA / ATERRAMENTO | H6: ANÁLISE DE RISCO DO PROJETO DE SPDA | I6: 0 | J6: 44136
A7: K19-204-FER-MC-004 | C7: Filtragem Cerâmica de Concentrado | D7: PROJETO BASICO | E7: FERRO+ MINERAÇÃO S.A | F7: FILTRAGEM CERÂMICA DE CONCENTRADO | G7: SPDA / ATERRAMENTO | H7: ANÁLISE DE RISCO DO PROJETO DE SPDA | I7: 0 | J7: 44136
A8: K19-204-FER-MC-005 | C8: Filtragem e Eletrocentro Prensa de Rejeito | D8: PROJETO BASICO | E8: FERRO+ MINERAÇÃO S.A | F8: FILTRAGEM E ELETROCENTRO PRENSA DE REJEITO | G8: SPDA / ATERRAMENTO | H8: ANÁLISE DE RISCO DO PROJETO DE SPDA | I8: 0 | J8: 44075
A9: K19-204-FER-MC-006 | C9: Escritório Administrativo 1 | D9: PROJETO BASICO | E9: FERRO+ MINERAÇÃO S.A | F9: ESCRITÓRIO ADMINISTRATIVO 1 | G9: SPDA / ATERRAMENTO | H9: ANÁLISE DE RISCO DO PROJETO DE SPDA | I9: 0 | J9: 44136
A10: K19-204-FER-MC-008 | C10: Geologia/Geotecnia | D10: PROJETO BASICO | E10: FERRO+ MINERAÇÃO S.A | F10: GEOLOGIA / GEOTECNIA | G10: SPDA / ATERRAMENTO | H10: ANÁLISE DE RISCO DO PROJETO DE SPDA | I10: 0 | J10: 44075
A11: K19-204-FER-MC-009 | B11: 6140344 | C11: Planta Moinho de Rolos | D11: PROJETO BASICO | E11: FERRO+ MINERAÇÃO S.A | F11: PLANTA MOINHO DE ROLOS | G11: SPDA / ATERRAMENTO | H11: ANÁLISE DE RISCO DO PROJETO DE SPDA | I11: 0 | J11: 44075
A12: K19-204-FER-MC-010 | C12: Fábrica de Placas e Container Meio Ambiente | D12: PROJETO BASICO | E12: FERRO+ MINERAÇÃO S.A | F12: FÁBRICA DE PLACAS E CONTAINER MEIO AMBIENTE | G12: SPDA / ATERRAMENTO | H12: ANÁLISE DE RISCO DO PROJETO DE SPDA | I12: 0 | J12: 44136
A13: K19-204-FER-MC-011 | C13: Portaria 1 e Lavador de Rodas | D13: PROJETO BASICO | E13: FERRO+ MINERAÇÃO S.A | F13: PORTARIA 1 E LAVADOR DE RODAS | G13: SPDA / ATERRAMENTO | H13: ANÁLISE DE RISCO DO PROJETO DE SPDA | I13: 0 | J13: 44136
A14: K19-204-FER-MC-012 | C14: Portaria 2 | D14: PROJETO BASICO | E14: FERRO+ MINERAÇÃO S.A | F14: PORTARIA 2 | G14: SPDA / ATERRAMENTO | H14: ANÁLISE DE RISCO DO PROJETO DE SPDA | I14: 0 | J14: 44136
A15: K19-204-FER-MC-013 | C15: Contêineres Próximos à Portaria 1 | D15: PROJETO BASICO | E15: FERRO+ MINERAÇÃO S.A | F15: CONTÊINERES PRÓXIMOS À PORTARIA 1 | G15: SPDA / ATERRAMENTO | H15: ANÁLISE DE RISCO DO PROJETO DE SPDA | I15: 0 | J15: 44075
A16: K19-204-FER-MC-014 | C16: Quiosque | D16: PROJETO BASICO | E16: FERRO+ MINERAÇÃO S.A | F16: QUIOSQUE | G16: SPDA / ATERRAMENTO | H16: ANÁLISE DE RISCO DO PROJETO DE SPDA | I16: 0 | J16: 44136
A17: K19-204-FER-MC-015 | C17: Oficina de Equipamentos | D17: PROJETO BASICO | E17: FERRO+ MINERAÇÃO S.A | F17: OFICINA DE EQUIPAMENTOS | G17: SPDA / ATERRAMENTO | H17: ANÁLISE DE RISCO DO PROJETO DE SPDA | I17: 0 | J17: 44075
A18: K19-204-FER-MC-016 | C18: Área de Canteiro de Obras | D18: PROJETO BASICO | E18: FERRO+ MINERAÇÃO S.A | F18: ÁREA DE CANTEIROS DE OBRAS | G18: SPDA / ATERRAMENTO | H18: ANÁLISE DE RISCO DO PROJETO DE SPDA | I18: 0 | J18: 44075
A19: K19-204-FER-MC-018 | C19: Caixas Australianas | D19: PROJETO BASICO | E19: FERRO+ MINERAÇÃO S.A | F19: CAIXAS AUSTRALIANAS | G19: SPDA / ATERRAMENTO | H19: ANÁLISE DE RISCO DO PROJETO DE SPDA | I19: 1 | J19: 44136
A20: K19-204-FER-MC-019 | C20: Logística e TI | D20: PROJETO BASICO | E20: FERRO+ MINERAÇÃO S.A | F20: LOGÍSTICA E TI | G20: SPDA / ATERRAMENTO | H20: ANÁLISE DE RISCO DO PROJETO DE SPDA | I20: 0 | J20: 44136
A21: K19-204-FER-MC-020 | C21: Área da Balança | D21: PROJETO BASICO | E21: FERRO+ MINERAÇÃO S.A | F21: ÁREA DA BALANÇA | G21: SPDA / ATERRAMENTO | H21: ANÁLISE DE RISCO DO PROJETO DE SPDA | I21: 0 | J21: 44136
A22: K19-204-FER-MC-021
A23: K19-204-FER-MC-022 | C23: Pátio de Reutilizaveis | D23: PROJETO BASICO | E23: FERRO+ MINERAÇÃO S.A | F23: PÁTIO DE REUTILIZAVEIS | G23: SPDA / ATERRAMENTO | H23: ANÁLISE DE RISCO DO PROJETO DE SPDA | I23: 0 | J23: 44075
A24: K19-204-FER-MC-023 | C24: Posto de Combustível | D24: PROJETO BASICO | E24: FERRO+ MINERAÇÃO S.A | F24: POSTO DE COMBUSTÍVEL | G24: SPDA / ATERRAMENTO | H24: ANÁLISE DE RISCO DO PROJETO DE SPDA | I24: 0 | J24: 44136
A25: K19-204-FER-MC-024 | C25: Restaurante e Vestiário | D25: PROJETO BASICO | E25: FERRO+ MINERAÇÃO S.A | F25: RESTAURANTE E VESTIÁRIO | G25: SPDA / ATERRAMENTO | H25: ANÁLISE DE RISCO DO PROJETO DE SPDA | I25: 1 | J25: 44136
A26: K19-204-FER-MC-025 | C26: Área das Peneiras da Mina | D26: PROJETO BASICO | E26: FERRO+ MINERAÇÃO S.A | F26: ÁREA DAS PENEIRAS DA MINA | G26: SPDA / ATERRAMENTO | H26: ANÁLISE DE RISCO DO PROJETO DE SPDA | I26: 0 | J26: 44075
A27: K19-204-FER-MC-026 | C27: Ponto de Ônibus | D27: PROJETO BASICO | E27: FERRO+ MINERAÇÃO S.A | F27: PONTO DE ÔNIBUS | G27: SPDA / ATERRAMENTO | H27: ANÁLISE DE RISCO DO PROJETO DE SPDA | I27: 0 | J27: 44075
A28: K19-204-FER-MC-027 | C28: Área de Classificação Próxima ao Meio Ambiente | D28: PROJETO BASICO | E28: FERRO+ MINERAÇÃO S.A | F28: ÁREA DE CLASSIFICAÇÃO PRÓXIMA AO MEIO AMBIENTE | G28: SPDA / ATERRAMENTO | H28: ANÁLISE DE RISCO DO PROJETO DE SPDA | I28: 0 | J28: 44075
A29: K19-204-FER-MC-028 | C29: Parada de Segurança | D29: PROJETO BASICO | E29: FERRO+ MINERAÇÃO S.A | F29: PARADA DE SEGURANÇA | G29: SPDA / ATERRAMENTO | H29: ANÁLISE DE RISCO DO PROJETO DE SPDA | I29: 0 | J29: 44075
A30: K19-204-FER-MC-030 | C30: Almoxarifado e Depósito de Materiais | D30: PROJETO BASICO | E30: FERRO+ MINERAÇÃO S.A | F30: ALMOXARIFADO E DEPÓSITO DE MATERIAIS | G30: SPDA / ATERRAMENTO | H30: ANÁLISE DE RISCO DO PROJETO DE SPDA | I30: 0 | J30: 44136
A31: K19-204-FER-MC-031 | C31: Oficina ITM | D31: PROJETO BASICO | E31: FERRO+ MINERAÇÃO S.A | F31: OFICINA ITM | G31: SPDA / ATERRAMENTO | H31: ANÁLISE DE RISCO DO PROJETO DE SPDA | I31: 0 | J31: 44075
A32: K19-204-FER-MC-032 | C32: Captação Sítio | D32: PROJETO BASICO | E32: FERRO+ MINERAÇÃO S.A | F32: CAPTAÇÃO SÍTIO | G32: SPDA / ATERRAMENTO | H32: ANÁLISE DE RISCO DO PROJETO DE SPDA | I32: 0 | J32: 44136
A33: K19-204-FER-MC-033 | C33: Josino | D33: PROJETO BASICO | E33: FERRO+ MINERAÇÃO S.A | F33: JOSINO | G33: SPDA / ATERRAMENTO | H33: ANÁLISE DE RISCO DO PROJETO DE SPDA | I33: 0 | J33: 44136
A34: K19-204-FER-MC-034 | C34: Smartmine e Container Gestão Contratos | D34: PROJETO BASICO | E34: FERRO+ MINERAÇÃO S.A | F34: SMARTMINE E CONTAINER GESTÃO CONTRATOS | G34: SPDA / ATERRAMENTO | H34: ANÁLISE DE RISCO DO PROJETO DE SPDA | I34: 0 | J34: 44075
A35: K19-204-FER-MC-035 | C35: Laboratório | D35: PROJETO BASICO | E35: FERRO+ MINERAÇÃO S.A | F35: LABORATÓRIO | G35: SPDA / ATERRAMENTO | H35: ANÁLISE DE RISCO DO PROJETO DE SPDA | I35: 0 | J35: 44136
A36: K19-204-FER-MC-036 | B36: 20210369268 | C36: Galpão de Treinamento | D36: PROJETO BASICO | E36: FERRO+ MINERAÇÃO S.A | F36: GALPÃO DE TREINAMENTO | G36: SPDA / ATERRAMENTO | H36: ANÁLISE DE RISCO DO PROJETO DE SPDA | I36: 0 | J36: 44075
A37: K19-204-FER-MC-037 | C37: Planta Piloto ITM | D37: PROJETO BASICO | E37: FERRO+ MINERAÇÃO S.A | F37: PLANTA PILOTO ITM | G37: SPDA / ATERRAMENTO | H37: ANÁLISE DE RISCO DO PROJETO DE SPDA | I37: 0 | J37: 44075
A38: K19-204-FER-MC-038 | C38: Poço Artesiano 1 | D38: PROJETO BASICO | E38: FERRO+ MINERAÇÃO S.A | F38: POÇO ARTESIANO 1 | G38: SPDA / ATERRAMENTO | H38: ANÁLISE DE RISCO DO PROJETO DE SPDA | I38: 0 | J38: 44136
A39: K19-204-FER-MC-039 | C39: Poço Artesiano 2 | D39: PROJETO BASICO | E39: FERRO+ MINERAÇÃO S.A | F39: POÇO ARTESIANO 2 | G39: SPDA / ATERRAMENTO | H39: ANÁLISE DE RISCO DO PROJETO DE SPDA | I39: 0 | J39: 44136
A40: K19-204-FER-MC-040 | C40: Rebritagens 1 e 2 | D40: PROJETO BASICO | E40: FERRO+ MINERAÇÃO S.A | F40: REBRITAGENS 1 E 2 | G40: SPDA / ATERRAMENTO | H40: ANÁLISE DE RISCO DO PROJETO DE SPDA | I40: 0 | J40: 44136
...

Sheet RIs
C1: Ferro+ - Ferro+ Mineração S.A
C2: CONTRATO: 089/2026 - Empresa: MSI Engenharia e Tecnologia LTDA
A3: Número | B3: ART | C3: Descrição da Área | D3: Título 1 | E3: Título 2 | F3: Título 3 | G3: Título 4 | H3: Título 5 | I3: Revisão | J3: Data de Emissão | K3: Número MSI | L3: Número J.Mendes | M3: Não Conformidade - Descrição | N3: Severidade | O3: Status | P3: Responsável | Q3: Data
A4: K19-204-FER-RI-001 | B4: 6140206 | C4: Classificação | D4: PROJETO BASICO | E4: FERRO+ MINERAÇÃO S.A | F4: CLASSIFICAÇÃO | G4: SPDA / ATERRAMENTO | H4: RELATÓRIO DE INSPEÇÃO | I4: 0 | J4: 44013
A5: K19-204-FER-RI-002 | B5: 6140221 | C5: Separação Magnética | D5: PROJETO BASICO | E5: FERRO+ MINERAÇÃO S.A | F5: SEPARAÇÃO MAGNÉTICA | G5: SPDA / ATERRAMENTO | H5: RELATÓRIO DE INSPEÇÃO | I5: 0 | J5: 44013
A6: K19-204-FER-RI-003 | B6: 6140233 | C6: Britagem | D6: PROJETO BASICO | E6: FERRO+ MINERAÇÃO S.A | F6: BRITAGEM | G6: SPDA / ATERRAMENTO | H6: RELATÓRIO DE INSPEÇÃO | I6: 0 | J6: 44013
A7: K19-204-FER-RI-004 | B7: 6140258 | C7: Filtragem Cerâmica de Concentrado | D7: PROJETO BASICO | E7: FERRO+ MINERAÇÃO S.A | F7: FILTRAGEM CERÂMICA DE CONCENTRADO | G7: SPDA / ATERRAMENTO | H7: RELATÓRIO DE INSPEÇÃO | I7: 0 | J7: 44013
A8: K19-204-FER-RI-005 | B8: 6140297 | C8: Filtragem e Eletrocentro Prensa de Rejeito | D8: PROJETO BASICO | E8: FERRO+ MINERAÇÃO S.A | F8: FILTRAGEM E ELETROCENTRO PRENSA DE REJEITO | G8: SPDA / ATERRAMENTO | H8: RELATÓRIO DE INSPEÇÃO | I8: 0 | J8: 44013
A9: K19-204-FER-RI-006 | B9: 6140310 | C9: Escritório Administrativo 1 (Antigo) | D9: PROJETO BASICO | E9: FERRO+ MINERAÇÃO S.A | F9: ESCRITÓRIO ADMINISTRATIVO 1 (ANTIGO) | G9: SPDA / ATERRAMENTO | H9: RELATÓRIO DE INSPEÇÃO | I9: 0 | J9: 44013
A10: K19-204-FER-RI-007 | B10: 6140317 | C10: Escritório Administrativo (Novo) | D10: PROJETO BASICO | E10: FERRO+ MINERAÇÃO S.A | F10: ESCRITÓRIO ADMINISTRATIVO (NOVO) | G10: SPDA / ATERRAMENTO | H10: RELATÓRIO DE INSPEÇÃO | I10: 0 | J10: 44013
A11: K19-204-FER-RI-008 | B11: 6140329 | C11: Geologia/Geotecnia | D11: PROJETO BASICO | E11: FERRO+ MINERAÇÃO S.A | F11: GEOLOGIA/GEOTECNIA | G11: SPDA / ATERRAMENTO | H11: RELATÓRIO DE INSPEÇÃO | I11: 0 | J11: 44013
A12: K19-204-FER-RI-009 | B12: 6140344 | C12: Planta Moinho de Rolos | D12: PROJETO BASICO | E12: FERRO+ MINERAÇÃO S.A | F12: PLANTA MOINHO DE ROLOS | G12: SPDA / ATERRAMENTO | H12: RELATÓRIO DE INSPEÇÃO | I12: 0 | J12: 44013
A13: K19-204-FER-RI-010 | B13: 6140390 | C13: Meio Ambiente/Comunicação | D13: PROJETO BASICO | E13: FERRO+ MINERAÇÃO S.A | F13: MEIO AMBIENTE/COMUNICAÇÃO | G13: SPDA / ATERRAMENTO | H13: RELATÓRIO DE INSPEÇÃO | I13: 0 | J13: 44013
A14: K19-204-FER-RI-011 | B14: 6140401 | C14: Portaria 1 | D14: PROJETO BASICO | E14: FERRO+ MINERAÇÃO S.A | F14: PORTARIA 1 | G14: SPDA / ATERRAMENTO | H14: RELATÓRIO DE INSPEÇÃO | I14: 0 | J14: 44013
A15: K19-204-FER-RI-012 | B15: 6140410 | C15: Portaria 2 | D15: PROJETO BASICO | E15: FERRO+ MINERAÇÃO S.A | F15: PORTARIA 2 | G15: SPDA / ATERRAMENTO | H15: RELATÓRIO DE INSPEÇÃO | I15: 0 | J15: 44013
... A48: K19-204-FER-RI-045 | B48: 6141813 | C48: Subestação 138KV E CCM | D48: PROJETO BASICO | E48: FERRO+ MINERAÇÃO S.A | F48: SUBESTAÇÃO 138KV E CCM | G48: SPDA / ATERRAMENTO | H48: RELATÓRIO DE INSPEÇÃO | I48: 0 | J48: 44013
A49: K19-204-FER-RI-046 | C49: Mirante. | D49: PROJETO BASICO | E49: FERRO+ MINERAÇÃO S.A | F49: MIRANTE | G49: SPDA / ATERRAMENTO | H49: RELATÓRIO DE INSPEÇÃO | I49: 0 | J49: 44197
A50: K19-204-FER-RI-047 | C50: Canteiros de obras VMF | D50: PROJETO BASICO | E50: FERRO+ MINERAÇÃO S.A | F50: CANTEIROS DE OBRAS VMF | G50: SPDA / ATERRAMENTO | H50: RELATÓRIO DE INSPEÇÃO | I50: 0 | J50: 44409
A51: K19-204-FER-RI-048 | C51: Nova ETE Oficina | D51: PROJETO BASICO | E51: FERRO+ MINERAÇÃO S.A | F51: NOVA ETE OFICINA | G51: SPDA / ATERRAMENTO | H51: RELATÓRIO DE INSPEÇÃO | I51: 0 | J51: 44409
A52: K19-204-FER-RI-049 | C52: Tenda contratadas | D52: PROJETO BASICO | E52: FERRO+ MINERAÇÃO S.A | F52: TENDAS CONTRATADAS | G52: SPDA / ATERRAMENTO | H52: RELATÓRIO DE INSPEÇÃO | I52: 0 | J52: 44423
A53: K19-204-FER-RI-050 | C53: Nova ETE Principal | D53: PROJETO BASICO | E53: FERRO+ MINERAÇÃO S.A | F53: NOVA ETE PRINCIPAL | G53: SPDA / ATERRAMENTO | H53: RELATÓRIO DE INSPEÇÃO | I53: 0 | J53: 44424
A54: K19-204-FER-RI-051 | C54: Contêiner Elétrica | D54: PROJETO BASICO | E54: FERRO+ MINERAÇÃO S.A | F54: CONTÊINER ELÉTRICA | G54: SPDA / ATERRAMENTO | H54: RELATÓRIO DE INSPEÇÃO | I54: 0
A55: K19-204-FER-RI-052 | C55: Contêiner Peneira 1 | D55: PROJETO BASICO | E55: FERRO+ MINERAÇÃO S.A | F55: CONTÊINER PENEIRA 1 | G55: SPDA / ATERRAMENTO | H55: RELATÓRIO DE INSPEÇÃO | I55: 0
A56: K19-204-FER-RI-053 | C56: Contêiner RH | D56: PROJETO BASICO | E56: FERRO+ MINERAÇÃO S.A | F56: CONTÊINER RH | G56: SPDA / ATERRAMENTO | H56: RELATÓRIO DE INSPEÇÃO | I56: 0
A57: K19-204-FER-RI-054 | C57: Novo DIR | D57: PROJETO BASICO | E57: FERRO+ MINERAÇÃO S.A | F57: NOVO DIR | G57: SPDA / ATERRAMENTO | H57: RELATÓRIO DE INSPEÇÃO | I57: 0 | J57: 44629
A58: K19-204-FER-RI-055 | C58: Restaurante Anexo | D58: PROJETO BASICO | E58: FERRO+ MINERAÇÃO S.A | F58: RESTAURANTE ANEXO | G58: SPDA / ATERRAMENTO | H58: RELATÓRIO DE INSPEÇÃO | I58: 0 | J58: 44629
A59: K19-204-FER-RI-056 | C59: Torre de Telecomunicações TI/Meio Ambiente | D59: PROJETO BASICO | E59: FERRO+ MINERAÇÃO S.A | F59: TORRE DE TELECOMUNICAÇÃO | G59: SPDA / ATERRAMENTO | H59: RELATÓRIO DE INSPEÇÃO | I59: 0 | J59: 44629
A60: K19-204-FER-RI-057 | C60: Novo Peneiramento | D60: PROJETO BASICO | E60: FERRO+ MINERAÇÃO S.A | F60: NOVO PENEIRAMENTO | G60: SPDA / ATERRAMENTO | H60: RELATÓRIO DE INSPEÇÃO | I60: 0 | J60: 44629
A61: K19-204-FER-RI-058 | C61: Container Recepção da Portaria | D61: PROJETO BASICO | E61: FERRO+ MINERAÇÃO S.A | F61: CONTAINER RECEPÇÃO DA PORTARIA | G61: SPDA / ATERRAMENTO | H61: RELATÓRIO DE INSPEÇÃO | I61: 0 | J61: 44629
A62: K19-204-FER-RI-059 | C62: Guarita Pátio Sucatas | D62: PROJETO BASICO | E62: FERRO+ MINERAÇÃO S.A | F62: GUARITA PÁTIO SUCATAS | G62: SPDA / ATERRAMENTO | H62: RELATÓRIO DE INSPEÇÃO | I62: 0 | J62: 44629
A63: K19-204-FER-RI-060 | C63: Contêiner PM-05 | D63: PROJETO BASICO | E63: FERRO+ MINERAÇÃO S.A | F63: CONTÊINER PM-05 | G63: SPDA / ATERRAMENTO | H63: RELATÓRIO DE INSPEÇÃO | I63: 0 | J63: 44629
A64: K19-204-FER-RI-061 | C64: Tenda Oficina de Veículos | D64: PROJETO BASICO | E64: FERRO+ MINERAÇÃO S.A | F64: TENDA OFICINA DE VEÍCULOS | G64: SPDA / ATERRAMENTO | H64: RELATÓRIO DE INSPEÇÃO | I64: 0 | J64: 44629
A65: K19-204-FER-RI-062 | C65: Contêiner Ferramentaria PCM ITM | D65: PROJETO BASICO | E65: FERRO+ MINERAÇÃO S.A | F65: CONTEINER FERRAMENTARIA PCM ITM | G65: SPDA / ATERRAMENTO | H65: RELATÓRIO DE INSPEÇÃO | I65: 0 | J65: 44629
A66: K19-204-FER-RI-063 | C66: Depósito de Produtos Químicos | D66: PROJETO BASICO | E66: FERRO+ MINERAÇÃO S.A | F66: DEPÓSITO DE PRODUTOS QUÍMICOS | G66: SPDA / ATERRAMENTO | H66: RELATÓRIO DE INSPEÇÃO | I66: 0 | J66: 44677
A67: K19-204-FER-RI-064 | C67: Depósito de Resíduos | D67: PROJETO BASICO | E67: FERRO+ MINERAÇÃO S.A | F67: DEPÓSITO DE RESÍDUOS | G67: SPDA / ATERRAMENTO | H67: RELATÓRIO DE INSPEÇÃO | I67: 0 | J67: 44677
A68: K19-204-FER-RI-065 | C68: Oficina PM-04 | D68: PROJETO BASICO | E68: FERRO+ MINERAÇÃO S.A | F68: OFICINA PM-04 | G68: SPDA / ATERRAMENTO | H68: RELATÓRIO DE INSPEÇÃO | I68: 0 | J68: 44700
... A73: K19-204-FER-RI-070 | C73: Base de Bombas Novas | D73: PROJETO BASICO | E73: FERRO+ MINERAÇÃO S.A | F73: BASE DE BOMBAS NOVAS | G73: SPDA / ATERRAMENTO | H73: RELATÓRIO DE INSPEÇÃO | I73: 0 | J73: 44713
A74: K19-204-FER-RI-071 | C74: Classificação e Moagem nas Prensas de Rolos | D74: PROJETO BASICO | E74: FERRO+ MINERAÇÃO S.A | F74: CLASSIFICAÇÃO E MOAGEM NAS PRENSAS DE ROLOS | G74: SPDA / ATERRAMENTO | H74: RELATÓRIO DE INSPEÇÃO | I74: 0
A75: K19-204-FER-RI-072 | C75: Casa de Máquina | D75: PROJETO BASICO | E75: FERRO+ MINERAÇÃO S.A | F75: CASA DE MÁQUINA | G75: SPDA / ATERRAMENTO | H75: RELATÓRIO DE INSPEÇÃO | I75: 0
A76: K19-204-FER-RI-073 | C76: Espessadores | D76: PROJETO BASICO | E76: FERRO+ MINERAÇÃO S.A | F76: ESPESSADORES | G76: SPDA / ATERRAMENTO | H76: RELATÓRIO DE INSPEÇÃO | I76: 0
...

Sheet Controle
A1: CONTRATO: 089/2026 - Empresa: MSI Engenharia e Tecnologia LTDA
A2: Código da Área | B2: LD (ÁREA CRIADA) | C2: DEMARCAÇÃO NO QGIS | D2: ÁREA À SER CONSIDERADA | E2: Descrição da Área | F2: RI Inicial | G2: ART Inicial | H2: MC | I2: DE | J2: MD | K2: LM | L2: ADEQUAÇÃO % | Q2: Ampliação Volume | R2: RI Conforme / Atual | S2: Data de Emissão do Laudo completo (medição) | T2: Validade do Laudo completo (medição) | U2: Inspeção Semestral (IS) | V2: Data de Emissão do último Laudo (Completo / IS) | W2: Validade da Inspeção Semestral | X2: Execução adequação inspeção Visual | Y2: ART Final | Z2: Status | AA2: Dossiê | AB2: Observações e previsão p/ adequação | AC2: Pendências
L3: Captação | M3: Descida | N3: Aterramento | O3: DPS | P3: Geral
A4: 2 | B4: 1000 | C4: 001 | E4: Britagem | F4: K19-204-FER-RI-003-R00 | G4: 6140233 | H4: K19-204-FER-MC-003 | I4: K19-204-FER-DE-023 | J4: K19-204-FER-MD-023 | K4: K19-204-FER-LM-023 | L4: 1 | M4: 1 | N4: 1 | O4: 1 | P4: {=SUM(L4:O4/4)} -> 1 | Q4: 1 | R4: K19-204-FER-RI-003-R02 | S4: 44927 | T4: =S4+366*3 -> 46025 | U4: K19-204-FER-IS-048 | V4: 45689 | W4: =V4+31*6 -> 45875 | X4: 1 | Y4: MG20210510899 | Z4: SPDA Conforme | AA4: P4-A1 | AB4: Nuvem atualizada | AC4: OK
A5: 3 | B5: 2000 | C5: 002 | D5: UNIFICAR - REBRITAGEM 2 E CLASSIFICAÇÃO | E5: Classificação | F5: K19-204-FER-RI-001-R00 | G5: 6140206 | H5: K19-204-FER-MC-001 | I5: K19-204-FER-DE-021 | J5: K19-204-FER-MD-021 | K5: K19-204-FER-LM-021 | L5: 1 | M5: 1 | N5: 1 | O5: 1 | P5: {=SUM(L5:O5/4)} -> 1 | Q5: 1 | R5: K19-204-FER-RI-001-R01 | S5: 45474 | T5: =S5+366*3 -> 46572 | U5: K19-204-FER-IS-076 | V5: 45689 | W5: =V5+31*6 -> 45875 | X5: 1 | Y5: MG20210510755 | Z5: SPDA Conforme | AA5: P13-A1 | AB5: Nuvem atualizada | AC5: OK
B6: 2000 | C6: 002 | D6: UNIFICAR - REBRITAGEM 2 E CLASSIFICAÇÃO | E6: Moagem | F6: K19-204-FER-RI-071-R00 | G6: N.A | L6: 1 | M6: 1 | N6: 0.5 | O6: 1 | P6: {=SUM(L6:O6/4)} -> 0.875 | Q6: 1 | U6: - | X6: - | Y6: - | Z6: Em andamento | AB6: Nuvem atualizada | AC6: Realizar limpeza na área abaixo dos HRC-800. Resp. J. Mendes
B7: 2000 | C7: 002 | D7: UNIFICAR - REBRITAGEM 2 E CLASSIFICAÇÃO | E7: Espirais | F7: K19-204-FER-RI-041-R00 | G7: 6141756 | H7: K19-204-FER-MC-001 | I7: K19-204-FER-DE-021 | J7: K19-204-FER-MD-021 | K7: K19-204-FER-LM-021 | L7: 1 | M7: 1 | N7: 1 | O7: 1 | P7: {=SUM(L7:O7/4)} -> 1 | Q7: 1 | R7: K19-204-FER-RI-001-R01 | S7: 45474 | T7: =S7+366*3 -> 46572 | U7: K19-204-FER-IS-075 | V7: 45689 | W7: =V7+31*6 -> 45875 | X7: 1 | Y7: MG20210510755 | Z7: SPDA Conforme | AA7: P13-A1 | AB7: Nuvem atualizada | AC7: OK
A8: 5 | B8: 3000 | C8: 003 | E8: Separador Magnético | F8: K19-204-FER-RI-002-R00 | G8: 6140221 | H8: K19-204-FER-MC-002 | I8: K19-204-FER-DE-022 | J8: K19-204-FER-MD-022 | K8: K19-204-FER-LM-022 | L8: 1 | M8: 1 | N8: 1 | O8: 1 | P8: {=SUM(L8:O8/4)} -> 1 | Q8: 1 | R8: K19-204-FER-RI-002-R01 | S8: 45748 | T8: =S8+366*3 -> 46846 | U8: K19-204-FER-IS-013 | V8: 45748 | W8: =V8+31*6 -> 45934 | X8: 1 | Y8: 6140221 | Z8: SPDA Conforme | AA8: P14-A1 | AB8: Nuvem atualizada | AC8: OK
A9: 7 | B9: 4000 | C9: 004 | D9: UNIFICAR COMO - ESPESSADORES | E9: Tanque de Cal Filtragem | F9: K19-204-FER-RI-067-R00 | G9: 6140297 | H9: K19-204-FER-MC-005 | I9: K19-204-FER-DE-011 | J9: K19-204-FER-MD-011 | K9: K19-204-FER-LM-011 | L9: 1 | M9: 1 | N9: 1 | O9: 1 | P9: {=SUM(L9:O9/4)} -> 1 | Q9: 1 | R9: K19-204-FER-RI-067-R00 | S9: 44622 | T9: =S9+366*3 -> 45720 | U9: K19-204-FER-IS-032 | V9: 45689 | W9: =SUM(V9+186) -> 45875 | X9: 1 | Y9: MG20221153441 | Z9: SPDA Conforme | AA9: P7-A1 | AB9: Nuvem atualizada | AC9: OK
A10: 8 | B10: 4000 | C10: 004 | D10: UNIFICAR COMO - ESPESSADORES | E10: Floculantes | F10: K19-204-FER-RI-042-R00 | G10: 6141763 | H10: K19-204-FER-MC-002 | I10: K19-204-FER-DE-022 | J10: K19-204-FER-MD-022 | K10: K19-204-FER-LM-022 | L10: 1 | M10: 1 | N10: 1 | O10: 1 | P10: 1 | Q10: NA | R10: K19-204-FER-RI-002-R01 | S10: 44927 | T10: =S10+366*3 -> 46025 | U10: K19-204-FER-IS-018 | V10: 45689 | W10: =SUM(V10+186) -> 45875 | X10: 1 | Y10: 6141763 | Z10: SPDA Conforme | AA10: P14-A1 | AB10: Nuvem atualizada | AC10: OK
A11: 10 | B11: 4000 | C11: 004 | D11: UNIFICAR COMO - ESPESSADORES | E11: Espessadores | F11: K19-204-FER-RI-043-R00 | G11: 6141775 | H11: K19-204-FER-MC-002 | I11: K19-204-FER-DE-022 | J11: K19-204-FER-MD-022 | K11: K19-204-FER-LM-022 | L11: 1 | M11: 1 | N11: 1 | O11: 1 | P11: 1 | Q11: 1 | R11: K19-204-FER-RI-002-R01 | S11: 44927 | T11: =S11+366*3 -> 46025 | U11: K19-204-FER-IS-065 | V11: 45689 | W11: =SUM(V11+186) -> 45875 | X11: 1 | Y11: MG20221153489 | Z11: SPDA Conforme | AA11: P14-A1 | AB11: Nuvem atualizada | AC11: OK
A12: xx | B12: 4000 | C12: 004 | D12: UNIFICAR COMO - ESPESSADORES | E12: Galpão de Ácido Nitrico | F12: K19-204-FER-RI-044-R01 | G12: N.A | H12: K19-204-FER-MC-091 | I12: K19-204-FER-DE-065 | J12: K19-204-FER-MD-074 | K12: K19-204-FER-LM-074 | L12: 1 | M12: 1 | N12: 1 | O12: 1 | P12: 1 | Q12: NA | R12: K19-204-FER-RI-044-R01 | S12: 44927 | T12: =S12+366*3 -> 46025 | U12: K19-204-FER-IS-017 | V12: 45689 | W12: =SUM(V12+186) -> 45875 | X12: 1 | Y12: 6141789 | Z12: SPDA Conforme | AA12: P10-A3 | AB12: Nuvem atualizada | AC12: OK
B13: 4000 | C13: 004 | D13: UNIFICAR COMO - ESPESSADORES | E13: Tanques Agitadores | F13: K19-204-FER-RI-044-R00 | G13: 6141789 | H13: K19-204-FER-MC-091 | I13: K19-204-FER-DE-065 | J13: K19-204-FER-MD-074 | K13: K19-204-FER-LM-074 | L13: 1 | M13: 1 | N13: 1 | O13: 1 | P13: 1 | Q13: 1 | R13: K19-204-FER-RI-044-R01 | S13: 44927 | T13: =S13+366*3 -> 46025 | U13: K19-204-FER-IS-016 | V13: 45689 | W13: =SUM(V13+186) -> 45875 | X13: 1 | Y13: 6141789 | Z13: SPDA Conforme | AB13: Nuvem atualizada | AC13: OK
A14: 6 | B14: 5001 | C14: 005 | D14: UNIFICAR - FILTRAGEM CONCENTRADOS | E14: Filtragem Cerâmica de Concentrado | F14: K19-204-FER-RI-004-R00 | G14: 6140258 | H14: K19-204-FER-MC-004 | I14: K19-204-FER-DE-024 | J14: K19-204-FER-MD-024 | K14: K19-204-FER-LM-024 | L14: 1 | M14: 1 | N14: 1 | O14: 1 | P14: {=SUM(L14:O14/4)} -> 1 | Q14: 1 | R14: K19-204-FER-RI-004-R01 | S14: 45474 | T14: =S14+366*3 -> 46572 | U14: K19-204-FER-IS-014 | V14: 45689 | W14: =SUM(V14+186) -> 45875 | X14: 0 | Y14: MG20221153555 | Z14: SPDA Conforme | AA14: P13-A2 | AB14: Nuvem atualizada | AC14: OK
A15: xx | B15: 5001 | C15: 005 | D15: UNIFICAR - FILTRAGEM CONCENTRADOS | E15: Torre de Resfriamento | F15: K19-204-FER-RI-069-R00 | G15: N.A | H15: K19-204-FER-MC-085 | I15: K19-204-FER-DE-071 | J15: K19-204-FER-MD-069 | K15: K19-204-FER-LM-068 | L15: 1 | M15: 1 | N15: 1 | O15: 1 | P15: {=SUM(L15:O15/4)} -> 1 | Q15: NA | R15: K19-204-FER-RI-069-R01 | S15: 45047 | T15: =S15+366*3 -> 46145 | U15: K19-204-FER-IS-056 | V15: 45689 | W15: =SUM(V15+186) -> 45875 | X15: 1 | Y15: MG20221576004 | Z15: SPDA Conforme | AA15: P10-A2 | AB15: Nuvem atualizada | AC15: OK
A16: xx | B16: 5001 | C16: 005 | D16: UNIFICAR - FILTRAGEM CONCENTRADOS | E16: Casa de Máquinas | F16: K19-204-FER-RI-072-R00 | G16: N.A | H16: K19-204-FER-MC-085 | I16: K19-204-FER-DE-071 | J16: K19-204-FER-MD-069 | K16: K19-204-FER-LM-068 | L16: 1 | M16: 1 | N16: 1 | O16: 1 | P16: 1 | Q16: NA | R16: K19-204-FER-RI-069-R01 | S16: 45047 | T16: =S16+366*3 -> 46145 | U16: K19-204-FER-IS-057 | V16: 45689 | W16: =SUM(V16+186) -> 45875 | X16: 1 | Y16: MG20221576004 | Z16: SPDA Conforme | AB16: Nuvem atualizada | AC16: OK
A17: 7 | B17: 6006 | C17: 006 | D17: UNIFICAR - FILTRAGEM DE REJEITOS | E17: Filtragem de Prensa | F17: K19-204-FER-RI-005-R00 | G17: 6140297 | H17: K19-204-FER-MC-005 | I17: K19-204-FER-DE-063 | J17: K19-204-FER-MD-067 | K17: K19-204-FER-LM-067 | L17: 1 | M17: 1 | N17: 1 | O17: 1 | P17: {=SUM(L17:O17/4)} -> 1 | Q17: 1 | R17: K19-204-FER-RI-005-R02 | S17: 44836 | T17: =S17+366*3 -> 45934 | U17: K19-204-FER-IS-015 | V17: 45689 | W17: =SUM(V17+186) -> 45875 | X17: 0 | Y17: MG20221154140 | Z17: SPDA Conforme | AA17: P7-A1 | AB17: Nuvem atualizada | AC17: OK
A18: 52 | B18: 6006 | C18: 006 | D18: UNIFICAR - FILTRAGEM DE REJEITOS | E18: Eletrocentro Filtragem Prensa 1 | F18: K19-204-FER-RI-005-R00 | G18: 6140297 | H18: K19-204-FER-MC-005 | I18: K19-204-FER-DE-063 | J18: K19-204-FER-MD-067 | K18: K19-204-FER-LM-067 | L18: 1 | M18: 1 | N18: 1 | O18: 1 | P18: {=SUM(L18:O18/4)} -> 1 | Q18: NA | R18: K19-204-FER-RI-005-R02 | S18: 44986 | T18: =S18+366*3 -> 46084 | U18: K19-204-FER-IS-053 | V18: 45689 | W18: =SUM(V18+186) -> 45875 | X18: 1 | Y18: MG20221154140 | Z18: SPDA Conforme | AB18: Nuvem atualizada | AC18: OK
B19: 6006 | C19: 006 | D19: UNIFICAR - FILTRAGEM DE REJEITOS | E19: Eletrocentro Filtragem Prensa 2 | F19: K19-204-FER-RI-074-R00 | G19: 6140297 | H19: K19-204-FER-MC-005 | I19: K19-204-FER-DE-063 | J19: K19-204-FER-MD-067 | K19: K19-204-FER-LM-067 | L19: 1 | M19: 1 | N19: 1 | O19: 1 | P19: {=SUM(L19:O19/4)} -> 1 | Q19: NA | R19: K19-204-FER-RI-005-R02 | S19: 44986 | T19: =S19+366*3 -> 46084 | U19: K19-204-FER-IS-054 | V19: 45689 | W19: =SUM(V19+186) -> 45875 | X19: 1 | Y19: MG20221154140 | Z19: SPDA Conforme | AB19: Nuvem atualizada | AC19: OK
A20: xx | B20: 7001 | C20: 007 | D20: UNIFICAR - BOMBA DE ÁGUA | E20: Caixa Australianas 1 | F20: K19-204-FER-RI-018-R00 | G20: 6140561 | H20: K19-204-FER-MC-018 | I20: K19-204-FER-DE-015 | J20: K19-204-FER-MD-015 | K20: K19-204-FER-LM-015 | L20: 1 | M20: 1 | N20: 1 | O20: 1 | P20: {=SUM(L20:O20/4)} -> 1 | Q20: NA | R20: K19-204-FER-RI-018-R02 | S20: 45078 | T20: =S20+366*3 -> 46176 | U20: K19-204-FER-IS-021 | V20: 45689 | W20: =SUM(V20+186) -> 45875 | X20: 1 | Y20: 6140561 | Z20: SPDA Conforme | AA20: P11-A1 | AB20: Nuvem atualizada | AC20: OK
A21: xx | B21: 7001 | C21: 007 | D21: UNIFICAR - BOMBA DE ÁGUA | E21: Caixa Australianas 2 | F21: K19-204-FER-RI-018-R00 | G21: 6140561 | H21: K19-204-FER-MC-018 | I21: K19-204-FER-DE-015 | J21: K19-204-FER-MD-015 | K21: K19-204-FER-LM-015 | L21: 1 | M21: 1 | N21: 1 | O21: 1 | P21: {=SUM(L21:O21/4)} -> 1 | Q21: NA | R21: K19-204-FER-RI-018-R02 | S21: 45078 | T21: =S21+366*3 -> 46176 | U21: K19-204-FER-IS-019 | V21: 45689 | W21: =SUM(V21+186) -> 45875 | X21: 1 | Y21: 6140561 | Z21: SPDA Conforme | AA21: P11-A1 | AB21: Nuvem atualizada | AC21: OK
A22: xx | B22: 7001 | C22: 007 | D22: UNIFICAR - BOMBA DE ÁGUA | E22: Caixa Australianas 3 | F22: K19-204-FER-RI-018-R00 | G22: 6140561 | H22: K19-204-FER-MC-018 | I22: K19-204-FER-DE-015 | J22: K19-204-FER-MD-015 | K22: K19-204-FER-LM-015 | L22: 1 | M22: 1 | N22: 1 | O22: 1 | P22: {=SUM(L22:O22/4)} -> 1 | Q22: NA | R22: K19-204-FER-RI-018-R02 | S22: 45078 | T22: =S22+366*3 -> 46176 | U22: K19-204-FER-IS-020 | V22: 45689 | W22: =SUM(V22+186) -> 45875 | X22: 1 | Y22: 6140561 | Z22: SPDA Conforme | AA22: P11-A1 | AB22: Nuvem atualizada | AC22: OK
A23: xx | B23: 7001 | C23: 007 | D23: UNIFICAR - BOMBA DE ÁGUA | E23: Caixa Australianas 4 | F23: K19-204-FER-RI-018-R00 | G23: 6140561 | H23: K19-204-FER-MC-018 | I23: K19-204-FER-DE-015 | J23: K19-204-FER-MD-015 | K23: K19-204-FER-LM-015 | L23: 1 | M23: 1 | N23: 1 | O23: 1 | P23: {=SUM(L23:O23/4)} -> 1 | Q23: NA | R23: K19-204-FER-RI-018-R02 | S23: 45078 | T23: =S23+366*3 -> 46176 | U23: K19-204-FER-IS-022 | V23: 45689 | W23: =SUM(V23+186) -> 45875 | X23: 1 | Y23: MG20221153165 | Z23: SPDA Conforme | AA23: P11-A1 | AB23: Nuvem atualizada | AC23: OK
A24: 9 | B24: 7001 | C24: 007 | D24: UNIFICAR - BOMBA DE ÁGUA | E24: Eletrocentro Bombas de Água | F24: K19-204-FER-RI-089-R00 | G24: N.A | H24: K19-204-FER-MC-081 | I24: K19-204-FER-DE-068 | J24: K19-204-FER-MD-064 | K24: K19-204-FER-LM-064 | L24: 1 | M24: 1 | N24: 1 | O24: 1 | P24: 1 | Q24: NA | R24: K19-204-FER-RI-089-R00 | S24: 45078 | T24: =S24+366*3 -> 46176 | U24: K19-204-FER-IS-071 | V24: 45689 | W24: =SUM(V24+186) -> 45875 | X24: 1 | Y24: MG20232225407 | Z24: SPDA Conforme | AA24: P11-A2 | AB24: Nuvem atualizada | AC24: OK
A25: 9 | B25: 7001 | C25: 007 | D25: UNIFICAR - BOMBA DE ÁGUA | E25: Bombas de Água | F25: K19-204-FER-RI-029-R00 | G25: 6140728 | H25: K19-204-FER-MC-018 | I25: K19-204-FER-DE-015 | J25: K19-204-FER-MD-015 | K25: K19-204-FER-LM-015 | L25: 1 | M25: 1 | N25: 1 | O25: 1 | P25: {=SUM(L25:O25/4)} -> 1 | Q25: NA | R25: K19-204-FER-RI-018-R02 | S25: 45078 | T25: =S25+366*3 -> 46176 | U25: K19-204-FER-IS-072 | V25: 45689 | W25: =SUM(V25+186) -> 45875 | X25: 0 | Y25: 6140728 | Z25: SPDA Conforme | AA25: P11-A1 | AB25: Nuvem atualizada | AC25: OK
